
<<o>>Mon Aug 19 20:40:10 2019<<o>>
Traceback (most recent call last):
  File "E:\Desktop\PyProject\Pydctq\dyrigin.py", line 87, in connect
    raise Exception('Can connect try again')
Exception: Can connect try again

-->Error:0	Count:0
<<o>>Mon Aug 19 20:40:10 2019<<o>>
NoneType: None

-->Error:0	Count:0
<<o>>Tue Aug 20 16:10:21 2019<<o>>
Traceback (most recent call last):
  File "E:\Desktop\PyProject\Pydctq\dyrigin.py", line 87, in connect
    raise Exception('Can connect try again')
Exception: Can connect try again

-->Error:0	Count:0
<<o>>Tue Aug 20 16:10:21 2019<<o>>
NoneType: None

-->Error:0	Count:0
<<o>>Tue Aug 20 16:10:24 2019<<o>>
Traceback (most recent call last):
  File "E:\Desktop\PyProject\Pydctq\dyrigin.py", line 87, in connect
    raise Exception('Can connect try again')
Exception: Can connect try again

-->Error:0	Count:0
<<o>>Tue Aug 20 16:10:24 2019<<o>>
NoneType: None

-->Error:0	Count:0
<<o>>Wed Aug 21 21:02:51 2019<<o>>
Traceback (most recent call last):
  File "E:\Desktop\PyProject\Pydctq\dyrigin.py", line 87, in connect
    raise Exception('Can connect try again')
Exception: Can connect try again

-->Error:0	Count:0
<<o>>Wed Aug 21 21:02:51 2019<<o>>
NoneType: None

-->Error:0	Count:0
<<o>>Fri Aug 23 21:14:48 2019<<o>>
Traceback (most recent call last):
  File "E:\Desktop\PyProject\Pydctq\dyrigin.py", line 87, in connect
    raise Exception('Can connect try again')
Exception: Can connect try again

-->Error:0	Count:0
<<o>>Fri Aug 23 21:14:48 2019<<o>>
NoneType: None

-->Error:0	Count:0
<<o>>Fri Aug 23 21:17:49 2019<<o>>
Traceback (most recent call last):
  File "E:\Desktop\PyProject\Pydctq\dyrigin.py", line 87, in connect
    raise Exception('Can connect try again')
Exception: Can connect try again

-->Error:0	Count:0
<<o>>Fri Aug 23 21:17:49 2019<<o>>
NoneType: None

-->Error:0	Count:0
<<o>>Fri Aug 23 21:18:17 2019<<o>>
Traceback (most recent call last):
  File "E:\Desktop\PyProject\Pydctq\dyrigin.py", line 79, in connect
    lietruyen()
  File "E:\Desktop\PyProject\Pydctq\dyrigin.py", line 132, in lietruyen
    print('liệt truyện')
  File "E:\python64x\lib\encodings\cp1252.py", line 19, in encode
    return codecs.charmap_encode(input,self.errors,encoding_table)[0]
UnicodeEncodeError: 'charmap' codec can't encode character '\u1ec7' in position 2: character maps to <undefined>

-->Error:0	Count:0
<<o>>Fri Aug 23 21:18:18 2019<<o>>
NoneType: None

-->Error:0	Count:0
<<o>>Fri Aug 23 21:18:42 2019<<o>>
Traceback (most recent call last):
  File "E:\Desktop\PyProject\Pydctq\dyrigin.py", line 79, in connect
    lietruyen()
  File "E:\Desktop\PyProject\Pydctq\dyrigin.py", line 132, in lietruyen
    print('liệt truyện')
  File "E:\python64x\lib\encodings\cp1252.py", line 19, in encode
    return codecs.charmap_encode(input,self.errors,encoding_table)[0]
UnicodeEncodeError: 'charmap' codec can't encode character '\u1ec7' in position 2: character maps to <undefined>

-->Error:0	Count:0
<<o>>Fri Aug 23 21:18:42 2019<<o>>
NoneType: None

-->Error:0	Count:0
<<o>>Fri Aug 23 21:19:26 2019<<o>>
Traceback (most recent call last):
  File "E:\Desktop\PyProject\Pydctq\dyrigin.py", line 79, in connect
    lietruyen()
  File "E:\Desktop\PyProject\Pydctq\dyrigin.py", line 132, in lietruyen
    print('liệt truyện')
  File "E:\python64x\lib\encodings\cp1252.py", line 19, in encode
    return codecs.charmap_encode(input,self.errors,encoding_table)[0]
UnicodeEncodeError: 'charmap' codec can't encode character '\u1ec7' in position 2: character maps to <undefined>

-->Error:0	Count:0
<<o>>Fri Aug 23 21:19:26 2019<<o>>
NoneType: None

-->Error:0	Count:0
<<o>>Fri Aug 23 21:26:03 2019<<o>>
Traceback (most recent call last):
  File "E:\Desktop\PyProject\Pydctq\dyrigin.py", line 87, in connect
    raise Exception('Can connect try again')
Exception: Can connect try again

-->Error:0	Count:0
<<o>>Fri Aug 23 21:26:03 2019<<o>>
NoneType: None

-->Error:0	Count:0
<<o>>Tue Aug 27 22:03:38 2019<<o>>
Traceback (most recent call last):
  File "E:\Desktop\PyProject\Pydctq\dyrigin.py", line 87, in connect
    raise Exception('Can connect try again')
Exception: Can connect try again

-->Error:0	Count:0
<<o>>Tue Aug 27 22:03:38 2019<<o>>
NoneType: None

-->Error:0	Count:0
<<o>>Sat Aug 31 09:01:09 2019<<o>>
Traceback (most recent call last):
  File "E:\Desktop\PyProject\Pydctq\dyrigin.py", line 87, in connect
    raise Exception('Can connect try again')
Exception: Can connect try again

-->Error:0	Count:0
<<o>>Sat Aug 31 09:01:09 2019<<o>>
NoneType: None

-->Error:0	Count:0
<<o>>Sun Sep  1 15:50:22 2019<<o>>
Traceback (most recent call last):
  File "E:\Desktop\PyProject\Pydctq\dyrigin.py", line 87, in connect
    raise Exception('Can connect try again')
Exception: Can connect try again

-->Error:0	Count:0
<<o>>Sun Sep  1 15:50:22 2019<<o>>
NoneType: None

-->Error:0	Count:0
<<o>>Sun Sep  1 15:50:25 2019<<o>>
Traceback (most recent call last):
  File "E:\Desktop\PyProject\Pydctq\dyrigin.py", line 87, in connect
    raise Exception('Can connect try again')
Exception: Can connect try again

-->Error:0	Count:0
<<o>>Sun Sep  1 15:50:25 2019<<o>>
NoneType: None

-->Error:0	Count:0
<<o>>Sun Sep  1 15:50:38 2019<<o>>
Traceback (most recent call last):
  File "E:\Desktop\PyProject\Pydctq\dyrigin.py", line 77, in connect
    checkauto()
  File "E:\Desktop\PyProject\Pydctq\dyrigin.py", line 120, in checkauto
    openAuto()
  File "E:\Desktop\PyProject\Pydctq\dyrigin.py", line 533, in openAuto
    print('Đã tìm thấy auto tại x.y: ', posiconAutostr)
  File "E:\python64x\lib\encodings\cp1252.py", line 19, in encode
    return codecs.charmap_encode(input,self.errors,encoding_table)[0]
UnicodeEncodeError: 'charmap' codec can't encode character '\u0110' in position 0: character maps to <undefined>

-->Error:0	Count:0
<<o>>Sun Sep  1 15:50:38 2019<<o>>
NoneType: None

-->Error:0	Count:0
<<o>>Sun Sep  1 15:51:19 2019<<o>>
Traceback (most recent call last):
  File "E:\Desktop\PyProject\Pydctq\dyrigin.py", line 81, in connect
    dbomLinh()
  File "E:\Desktop\PyProject\Pydctq\dyrigin.py", line 431, in dbomLinh
    print('(*)-------Bơm TNS------(*)')
  File "E:\python64x\lib\encodings\cp1252.py", line 19, in encode
    return codecs.charmap_encode(input,self.errors,encoding_table)[0]
UnicodeEncodeError: 'charmap' codec can't encode character '\u01a1' in position 11: character maps to <undefined>

-->Error:0	Count:0
<<o>>Sun Sep  1 15:51:19 2019<<o>>
NoneType: None

-->Error:0	Count:0
<<o>>Sun Sep  1 16:03:38 2019<<o>>
Traceback (most recent call last):
  File "E:\Desktop\PyProject\Pydctq\dyrigin.py", line 500, in click_image
    position = imgfind.find(showpos=True)[0]
IndexError: list index out of range

-->Error:1	Count:5
<<o>>Tue Sep  3 04:25:39 2019<<o>>
Traceback (most recent call last):
  File "E:\Desktop\PyProject\Pydctq\dyrigin.py", line 87, in connect
    raise Exception('Can connect try again')
Exception: Can connect try again

-->Error:0	Count:0
<<o>>Tue Sep  3 04:25:39 2019<<o>>
NoneType: None

-->Error:0	Count:0
<<o>>Tue Sep  3 04:27:16 2019<<o>>
Traceback (most recent call last):
  File "E:\Desktop\PyProject\Pydctq\dyrigin.py", line 87, in connect
    raise Exception('Can connect try again')
Exception: Can connect try again

-->Error:0	Count:0
<<o>>Tue Sep  3 04:27:16 2019<<o>>
NoneType: None

-->Error:0	Count:0
<<o>>Tue Sep  3 04:27:28 2019<<o>>
Traceback (most recent call last):
  File "E:\Desktop\PyProject\Pydctq\dyrigin.py", line 77, in connect
    checkauto()
  File "E:\Desktop\PyProject\Pydctq\dyrigin.py", line 120, in checkauto
    openAuto()
  File "E:\Desktop\PyProject\Pydctq\dyrigin.py", line 533, in openAuto
    print('Đã tìm thấy auto tại x.y: ', posiconAutostr)
  File "E:\python64x\lib\encodings\cp1252.py", line 19, in encode
    return codecs.charmap_encode(input,self.errors,encoding_table)[0]
UnicodeEncodeError: 'charmap' codec can't encode character '\u0110' in position 0: character maps to <undefined>

-->Error:0	Count:0
<<o>>Tue Sep  3 04:27:28 2019<<o>>
NoneType: None

-->Error:0	Count:0
<<o>>Tue Sep  3 04:33:01 2019<<o>>
Traceback (most recent call last):
  File "E:\Desktop\PyProject\Pydctq\dyrigin.py", line 79, in connect
    lietruyen()
  File "E:\Desktop\PyProject\Pydctq\dyrigin.py", line 132, in lietruyen
    print('liệt truyện')
  File "E:\python64x\lib\encodings\cp1252.py", line 19, in encode
    return codecs.charmap_encode(input,self.errors,encoding_table)[0]
UnicodeEncodeError: 'charmap' codec can't encode character '\u1ec7' in position 2: character maps to <undefined>

-->Error:0	Count:0
<<o>>Tue Sep  3 04:33:01 2019<<o>>
NoneType: None

-->Error:0	Count:0
<<o>>Tue Sep  3 04:33:30 2019<<o>>
NoneType: None

-->Error:0	Count:0
<<o>>Tue Sep  3 04:36:54 2019<<o>>
NoneType: None

-->Error:0	Count:0
<<o>>Tue Sep  3 05:03:48 2019<<o>>
Traceback (most recent call last):
  File "E:\Desktop\PyProject\Pydctq\dyrigin.py", line 91, in connect
    raise Exception('Can connect try again')
Exception: Can connect try again

-->Error:0	Count:0
<<o>>Tue Sep  3 05:03:48 2019<<o>>
NoneType: None

-->Error:0	Count:0
<<o>>Tue Sep  3 05:05:29 2019<<o>>
Traceback (most recent call last):
  File "E:\Desktop\PyProject\Pydctq\dyrigin.py", line 90, in connect
    raise Exception('Can connect try again')
Exception: Can connect try again

-->Error:0	Count:0
<<o>>Tue Sep  3 05:05:29 2019<<o>>
NoneType: None

-->Error:0	Count:0
<<o>>Tue Sep  3 05:06:43 2019<<o>>
Traceback (most recent call last):
  File "E:\Desktop\PyProject\Pydctq\dyrigin.py", line 90, in connect
    raise Exception('Can connect try again')
Exception: Can connect try again

-->Error:0	Count:0
<<o>>Tue Sep  3 05:06:43 2019<<o>>
NoneType: None

-->Error:0	Count:0
<<o>>Tue Sep  3 13:17:47 2019<<o>>
Traceback (most recent call last):
  File "E:\Desktop\PyProject\Pydctq\dyrigin.py", line 90, in connect
    raise Exception('Can connect try again')
Exception: Can connect try again

-->Error:0	Count:0
<<o>>Tue Sep  3 13:17:47 2019<<o>>
NoneType: None

-->Error:0	Count:0
<<o>>Tue Sep  3 13:18:38 2019<<o>>
Traceback (most recent call last):
  File "E:\Desktop\PyProject\Pydctq\dyrigin.py", line 90, in connect
    raise Exception('Can connect try again')
Exception: Can connect try again

-->Error:0	Count:0
<<o>>Tue Sep  3 13:18:38 2019<<o>>
NoneType: None

-->Error:0	Count:0
<<o>>Tue Sep  3 13:35:57 2019<<o>>
NoneType: None

-->Error:0	Count:5
<<o>>Tue Sep  3 14:09:04 2019<<o>>
Traceback (most recent call last):
  File "E:\Desktop\PyProject\Pydctq\dyrigin.py", line 90, in connect
    raise Exception('Can connect try again')
Exception: Can connect try again

-->Error:0	Count:0
<<o>>Tue Sep  3 14:09:04 2019<<o>>
NoneType: None

-->Error:0	Count:0
<<o>>Tue Sep  3 14:09:57 2019<<o>>
Traceback (most recent call last):
  File "E:\Desktop\PyProject\Pydctq\dyrigin.py", line 89, in connect
    raise Exception('Can connect try again')
Exception: Can connect try again

-->Error:0	Count:0
<<o>>Tue Sep  3 14:09:57 2019<<o>>
NoneType: None

-->Error:0	Count:0
<<o>>Tue Sep  3 14:24:24 2019<<o>>
Traceback (most recent call last):
  File "dyrigin.py", line 89, in connect
    raise Exception('Can connect try again')
Exception: Can connect try again

-->Error:0	Count:0
<<o>>Tue Sep  3 14:24:24 2019<<o>>
NoneType: None

-->Error:0	Count:0
<<o>>Tue Sep  3 14:35:07 2019<<o>>
Traceback (most recent call last):
  File "dyrigin.py", line 89, in connect
    raise Exception('Can connect try again')
Exception: Can connect try again

-->Error:0	Count:0
<<o>>Tue Sep  3 14:35:07 2019<<o>>
NoneType: None

-->Error:0	Count:0
<<o>>Wed Sep  4 13:59:12 2019<<o>>
Traceback (most recent call last):
  File "E:\Desktop\PyProject\Pydctq\dyrigin.py", line 89, in connect
    raise Exception('Can connect try again')
Exception: Can connect try again

-->Error:0	Count:0
<<o>>Wed Sep  4 13:59:12 2019<<o>>
NoneType: None

-->Error:0	Count:0
<<o>>Thu Sep  5 14:08:54 2019<<o>>
NoneType: None

-->Error:0	Count:15
<<o>>Fri Sep  6 21:54:14 2019<<o>>
NoneType: None

-->Error:0	Count:15
<<o>>Thu Sep 12 12:59:03 2019<<o>>
Traceback (most recent call last):
  File "D:\Desktop\D.Destop\PyProject\Pydctq\dyrigin.py", line 85, in connect
    call(r'S:\"DATA bin"\Programs\NOX\Nox\bin\adb kill-server')
  File "C:\Python\Python36\lib\subprocess.py", line 267, in call
    with Popen(*popenargs, **kwargs) as p:
  File "C:\Python\Python36\lib\subprocess.py", line 709, in __init__
    restore_signals, start_new_session)
  File "C:\Python\Python36\lib\subprocess.py", line 997, in _execute_child
    startupinfo)
FileNotFoundError: [WinError 2] The system cannot find the file specified

During handling of the above exception, another exception occurred:

Traceback (most recent call last):
  File "D:\Desktop\D.Destop\PyProject\Pydctq\dyrigin.py", line 91, in connect
    except cv2.error:
NameError: name 'cv2' is not defined

-->Error:0	Count:0
<<o>>Thu Sep 12 12:59:24 2019<<o>>
Traceback (most recent call last):
  File "D:\Desktop\D.Destop\PyProject\Pydctq\dyrigin.py", line 85, in connect
    call(r'S:\"DATA bin"\Programs\NOX\Nox\bin\adb kill-server')
  File "C:\Python\Python36\lib\subprocess.py", line 267, in call
    with Popen(*popenargs, **kwargs) as p:
  File "C:\Python\Python36\lib\subprocess.py", line 709, in __init__
    restore_signals, start_new_session)
  File "C:\Python\Python36\lib\subprocess.py", line 997, in _execute_child
    startupinfo)
FileNotFoundError: [WinError 2] The system cannot find the file specified

During handling of the above exception, another exception occurred:

Traceback (most recent call last):
  File "D:\Desktop\D.Destop\PyProject\Pydctq\dyrigin.py", line 91, in connect
    except cv2.error:
NameError: name 'cv2' is not defined

-->Error:0	Count:0
<<o>>Thu Sep 12 12:59:55 2019<<o>>
Traceback (most recent call last):
  File "D:\Desktop\D.Destop\PyProject\Pydctq\dyrigin.py", line 85, in connect
    call(r'S:\"DATA bin"\Programs\NOX\Nox\bin\adb kill-server')
  File "C:\Python\Python36\lib\subprocess.py", line 267, in call
    with Popen(*popenargs, **kwargs) as p:
  File "C:\Python\Python36\lib\subprocess.py", line 709, in __init__
    restore_signals, start_new_session)
  File "C:\Python\Python36\lib\subprocess.py", line 997, in _execute_child
    startupinfo)
FileNotFoundError: [WinError 2] The system cannot find the file specified

During handling of the above exception, another exception occurred:

Traceback (most recent call last):
  File "D:\Desktop\D.Destop\PyProject\Pydctq\dyrigin.py", line 91, in connect
    except cv2.error:
NameError: name 'cv2' is not defined

-->Error:0	Count:0
<<o>>Thu Sep 12 13:00:10 2019<<o>>
Traceback (most recent call last):
  File "D:\Desktop\D.Destop\PyProject\Pydctq\dyrigin.py", line 77, in connect
    checkauto()
  File "D:\Desktop\D.Destop\PyProject\Pydctq\dyrigin.py", line 115, in checkauto
    if imgAuto.find(showpos=True):
  File "D:\Desktop\D.Destop\PyProject\Pydctq\Imagesearch.py", line 32, in find
    grayimg = cv2.cvtColor(rgb, cv2.COLOR_BGR2GRAY)
cv2.error: OpenCV(4.1.1) C:\projects\opencv-python\opencv\modules\imgproc\src\color.cpp:182: error: (-215:Assertion failed) !_src.empty() in function 'cv::cvtColor'


During handling of the above exception, another exception occurred:

Traceback (most recent call last):
  File "D:\Desktop\D.Destop\PyProject\Pydctq\dyrigin.py", line 91, in connect
    except cv2.error:
NameError: name 'cv2' is not defined

-->Error:0	Count:0
<<o>>Thu Sep 12 13:00:22 2019<<o>>
Traceback (most recent call last):
  File "D:\Desktop\D.Destop\PyProject\Pydctq\dyrigin.py", line 85, in connect
    call(r'S:\"DATA bin"\Programs\NOX\Nox\bin\adb kill-server')
  File "C:\Python\Python36\lib\subprocess.py", line 267, in call
    with Popen(*popenargs, **kwargs) as p:
  File "C:\Python\Python36\lib\subprocess.py", line 709, in __init__
    restore_signals, start_new_session)
  File "C:\Python\Python36\lib\subprocess.py", line 997, in _execute_child
    startupinfo)
FileNotFoundError: [WinError 2] The system cannot find the file specified

During handling of the above exception, another exception occurred:

Traceback (most recent call last):
  File "D:\Desktop\D.Destop\PyProject\Pydctq\dyrigin.py", line 91, in connect
    except cv2.error:
NameError: name 'cv2' is not defined

-->Error:0	Count:0
<<o>>Thu Sep 12 13:00:43 2019<<o>>
Traceback (most recent call last):
  File "D:\Desktop\D.Destop\PyProject\Pydctq\dyrigin.py", line 85, in connect
    call(r'S:\"DATA bin"\Programs\NOX\Nox\bin\adb kill-server')
  File "C:\Python\Python36\lib\subprocess.py", line 267, in call
    with Popen(*popenargs, **kwargs) as p:
  File "C:\Python\Python36\lib\subprocess.py", line 709, in __init__
    restore_signals, start_new_session)
  File "C:\Python\Python36\lib\subprocess.py", line 997, in _execute_child
    startupinfo)
FileNotFoundError: [WinError 2] The system cannot find the file specified

During handling of the above exception, another exception occurred:

Traceback (most recent call last):
  File "D:\Desktop\D.Destop\PyProject\Pydctq\dyrigin.py", line 91, in connect
    except cv2.error:
NameError: name 'cv2' is not defined

-->Error:0	Count:0
<<o>>Thu Sep 12 20:25:33 2019<<o>>
Traceback (most recent call last):
  File "D:\Desktop\D.Destop\PyProject\Pydctq\dyrigin.py", line 502, in click_image
    position = imgfind.find(showpos=True)[0]
IndexError: list index out of range

During handling of the above exception, another exception occurred:

Traceback (most recent call last):
  File "D:\Desktop\D.Destop\PyProject\Pydctq\dyrigin.py", line 81, in connect
    dbomLinh()
  File "D:\Desktop\D.Destop\PyProject\Pydctq\dyrigin.py", line 435, in dbomLinh
    click_image('//huanluyen.png')
  File "D:\Desktop\D.Destop\PyProject\Pydctq\dyrigin.py", line 511, in click_image
    check_loi_vethanh()
  File "D:\Desktop\D.Destop\PyProject\Pydctq\dyrigin.py", line 342, in check_loi_vethanh
    danh()
  File "D:\Desktop\D.Destop\PyProject\Pydctq\dyrigin.py", line 208, in danh
    DanhTiep()                  # opt2 check nút hồi thành --end
  File "D:\Desktop\D.Destop\PyProject\Pydctq\dyrigin.py", line 269, in DanhTiep
    giaotranh()
  File "D:\Desktop\D.Destop\PyProject\Pydctq\dyrigin.py", line 173, in giaotranh
    danh()
  File "D:\Desktop\D.Destop\PyProject\Pydctq\dyrigin.py", line 208, in danh
    DanhTiep()                  # opt2 check nút hồi thành --end
  File "D:\Desktop\D.Destop\PyProject\Pydctq\dyrigin.py", line 269, in DanhTiep
    giaotranh()
  File "D:\Desktop\D.Destop\PyProject\Pydctq\dyrigin.py", line 173, in giaotranh
    danh()
  File "D:\Desktop\D.Destop\PyProject\Pydctq\dyrigin.py", line 208, in danh
    DanhTiep()                  # opt2 check nút hồi thành --end
  File "D:\Desktop\D.Destop\PyProject\Pydctq\dyrigin.py", line 269, in DanhTiep
    giaotranh()
  File "D:\Desktop\D.Destop\PyProject\Pydctq\dyrigin.py", line 173, in giaotranh
    danh()
  File "D:\Desktop\D.Destop\PyProject\Pydctq\dyrigin.py", line 208, in danh
    DanhTiep()                  # opt2 check nút hồi thành --end
  File "D:\Desktop\D.Destop\PyProject\Pydctq\dyrigin.py", line 269, in DanhTiep
    giaotranh()
  File "D:\Desktop\D.Destop\PyProject\Pydctq\dyrigin.py", line 173, in giaotranh
    danh()
  File "D:\Desktop\D.Destop\PyProject\Pydctq\dyrigin.py", line 208, in danh
    DanhTiep()                  # opt2 check nút hồi thành --end
  File "D:\Desktop\D.Destop\PyProject\Pydctq\dyrigin.py", line 255, in DanhTiep
    print('Wait ', x)
OSError: [Errno 22] Invalid argument

During handling of the above exception, another exception occurred:

Traceback (most recent call last):
  File "D:\Desktop\D.Destop\PyProject\Pydctq\dyrigin.py", line 91, in connect
    except cv2.error:
NameError: name 'cv2' is not defined

-->Error:1	Count:4
<<o>>Fri Sep 13 21:37:17 2019<<o>>
Traceback (most recent call last):
  File "D:\Desktop\D.Destop\PyProject\Pydctq\dyrigin.py", line 502, in click_image
    position = imgfind.find(showpos=True)[0]
IndexError: list index out of range

During handling of the above exception, another exception occurred:

Traceback (most recent call last):
  File "D:\Desktop\D.Destop\PyProject\Pydctq\dyrigin.py", line 502, in click_image
    position = imgfind.find(showpos=True)[0]
IndexError: list index out of range

During handling of the above exception, another exception occurred:

Traceback (most recent call last):
  File "D:\Desktop\D.Destop\PyProject\Pydctq\dyrigin.py", line 81, in connect
    dbomLinh()
  File "D:\Desktop\D.Destop\PyProject\Pydctq\dyrigin.py", line 435, in dbomLinh
    click_image('//huanluyen.png')
  File "D:\Desktop\D.Destop\PyProject\Pydctq\dyrigin.py", line 511, in click_image
    check_loi_vethanh()
  File "D:\Desktop\D.Destop\PyProject\Pydctq\dyrigin.py", line 342, in check_loi_vethanh
    danh()
  File "D:\Desktop\D.Destop\PyProject\Pydctq\dyrigin.py", line 208, in danh
    DanhTiep()                  # opt2 check nút hồi thành --end
  File "D:\Desktop\D.Destop\PyProject\Pydctq\dyrigin.py", line 269, in DanhTiep
    giaotranh()
  File "D:\Desktop\D.Destop\PyProject\Pydctq\dyrigin.py", line 173, in giaotranh
    danh()
  File "D:\Desktop\D.Destop\PyProject\Pydctq\dyrigin.py", line 208, in danh
    DanhTiep()                  # opt2 check nút hồi thành --end
  File "D:\Desktop\D.Destop\PyProject\Pydctq\dyrigin.py", line 269, in DanhTiep
    giaotranh()
  File "D:\Desktop\D.Destop\PyProject\Pydctq\dyrigin.py", line 173, in giaotranh
    danh()
  File "D:\Desktop\D.Destop\PyProject\Pydctq\dyrigin.py", line 208, in danh
    DanhTiep()                  # opt2 check nút hồi thành --end
  File "D:\Desktop\D.Destop\PyProject\Pydctq\dyrigin.py", line 269, in DanhTiep
    giaotranh()
  File "D:\Desktop\D.Destop\PyProject\Pydctq\dyrigin.py", line 173, in giaotranh
    danh()
  File "D:\Desktop\D.Destop\PyProject\Pydctq\dyrigin.py", line 208, in danh
    DanhTiep()                  # opt2 check nút hồi thành --end
  File "D:\Desktop\D.Destop\PyProject\Pydctq\dyrigin.py", line 269, in DanhTiep
    giaotranh()
  File "D:\Desktop\D.Destop\PyProject\Pydctq\dyrigin.py", line 173, in giaotranh
    danh()
  File "D:\Desktop\D.Destop\PyProject\Pydctq\dyrigin.py", line 208, in danh
    DanhTiep()                  # opt2 check nút hồi thành --end
  File "D:\Desktop\D.Destop\PyProject\Pydctq\dyrigin.py", line 269, in DanhTiep
    giaotranh()
  File "D:\Desktop\D.Destop\PyProject\Pydctq\dyrigin.py", line 173, in giaotranh
    danh()
  File "D:\Desktop\D.Destop\PyProject\Pydctq\dyrigin.py", line 208, in danh
    DanhTiep()                  # opt2 check nút hồi thành --end
  File "D:\Desktop\D.Destop\PyProject\Pydctq\dyrigin.py", line 242, in DanhTiep
    dbomLinh()
  File "D:\Desktop\D.Destop\PyProject\Pydctq\dyrigin.py", line 435, in dbomLinh
    click_image('//huanluyen.png')
  File "D:\Desktop\D.Destop\PyProject\Pydctq\dyrigin.py", line 511, in click_image
    check_loi_vethanh()
  File "D:\Desktop\D.Destop\PyProject\Pydctq\dyrigin.py", line 342, in check_loi_vethanh
    danh()
  File "D:\Desktop\D.Destop\PyProject\Pydctq\dyrigin.py", line 208, in danh
    DanhTiep()                  # opt2 check nút hồi thành --end
  File "D:\Desktop\D.Destop\PyProject\Pydctq\dyrigin.py", line 269, in DanhTiep
    giaotranh()
  File "D:\Desktop\D.Destop\PyProject\Pydctq\dyrigin.py", line 173, in giaotranh
    danh()
  File "D:\Desktop\D.Destop\PyProject\Pydctq\dyrigin.py", line 208, in danh
    DanhTiep()                  # opt2 check nút hồi thành --end
  File "D:\Desktop\D.Destop\PyProject\Pydctq\dyrigin.py", line 269, in DanhTiep
    giaotranh()
  File "D:\Desktop\D.Destop\PyProject\Pydctq\dyrigin.py", line 173, in giaotranh
    danh()
  File "D:\Desktop\D.Destop\PyProject\Pydctq\dyrigin.py", line 208, in danh
    DanhTiep()                  # opt2 check nút hồi thành --end
  File "D:\Desktop\D.Destop\PyProject\Pydctq\dyrigin.py", line 255, in DanhTiep
    print('Wait ', x)
OSError: [Errno 22] Invalid argument

During handling of the above exception, another exception occurred:

Traceback (most recent call last):
  File "D:\Desktop\D.Destop\PyProject\Pydctq\dyrigin.py", line 91, in connect
    except cv2.error:
NameError: name 'cv2' is not defined

-->Error:2	Count:8